Traceback (most recent call last):
  File "/usr/local/lib/python3.11/dist-packages/jupyter_core/utils/__init__.py", line 154, in wrapped
    asyncio.get_running_loop()
RuntimeError: no running event loop

During handling of the above exception, another exception occurred:

Traceback (most recent call last):
  File "/usr/local/lib/python3.11/dist-packages/jupyter_cache/executors/utils.py", line 58, in single_nb_execution
    executenb(
  File "/usr/local/lib/python3.11/dist-packages/nbclient/client.py", line 1319, in execute
    return NotebookClient(nb=nb, resources=resources, km=km, **kwargs).execute()
           ^^^^^^^^^^^^^^^^^^^^^^^^^^^^^^^^^^^^^^^^^^^^^^^^^^^^^^^^^^^^^^^^^^^^^
  File "/usr/local/lib/python3.11/dist-packages/jupyter_core/utils/__init__.py", line 158, in wrapped
    return loop.run_until_complete(inner)
           ^^^^^^^^^^^^^^^^^^^^^^^^^^^^^^
  File "/usr/lib/python3.11/asyncio/base_events.py", line 654, in run_until_complete
    return future.result()
           ^^^^^^^^^^^^^^^
  File "/usr/local/lib/python3.11/dist-packages/nbclient/client.py", line 709, in async_execute
    await self.async_execute_cell(
  File "/usr/local/lib/python3.11/dist-packages/nbclient/client.py", line 1062, in async_execute_cell
    await self._check_raise_for_error(cell, cell_index, exec_reply)
  File "/usr/local/lib/python3.11/dist-packages/nbclient/client.py", line 918, in _check_raise_for_error
    raise CellExecutionError.from_cell_and_msg(cell, exec_reply_content)
nbclient.exceptions.CellExecutionError: An error occurred while executing the following cell:
------------------
# === Visualisasi Struktur Pohon ===
plt.figure(figsize=(12, 3))
plot_tree(
    clf,
    feature_names=["Panjang Tubuh (cm)", "Berat Tubuh (kg)"],
    class_names=le.classes_,  # gunakan label string hasil encoding
    filled=True,
    rounded=True,
    impurity=True  # tampilkan nilai Gini
)
plt.title("Decision Tree untuk Panthera onca vs Panthera pardus")
plt.tight_layout()
plt.show()

------------------


[0;31m---------------------------------------------------------------------------[0m
[0;31mNameError[0m                                 Traceback (most recent call last)
[0;32m<ipython-input-4-755702168>[0m in [0;36m<cell line: 0>[0;34m()[0m
[1;32m      1[0m [0;31m# === Visualisasi Struktur Pohon ===[0m[0;34m[0m[0;34m[0m[0m
[1;32m      2[0m [0mplt[0m[0;34m.[0m[0mfigure[0m[0;34m([0m[0mfigsize[0m[0;34m=[0m[0;34m([0m[0;36m12[0m[0;34m,[0m [0;36m3[0m[0;34m)[0m[0;34m)[0m[0;34m[0m[0;34m[0m[0m
[0;32m----> 3[0;31m plot_tree(
[0m[1;32m      4[0m     [0mclf[0m[0;34m,[0m[0;34m[0m[0;34m[0m[0m
[1;32m      5[0m     [0mfeature_names[0m[0;34m=[0m[0;34m[[0m[0;34m"Panjang Tubuh (cm)"[0m[0;34m,[0m [0;34m"Berat Tubuh (kg)"[0m[0;34m][0m[0;34m,[0m[0;34m[0m[0;34m[0m[0m

[0;31mNameError[0m: name 'plot_tree' is not defined

